Workbook
Name baseline: '[1]2.일정추적'!#REF!
Name baseline: '[1]2.일정추적'!#REF!
Name rpt_date: '[1]1.요약'!$C$4
Name T01_컬럼정보_Query: #REF!
Name T01_컬럼정보_Query: #REF!
Name tol: '[1]4.1공수분석_개발'!$J$6
Name ㄴ: #REF!
Name ㄴ: #REF!
Name 버전: #REF!
Name 버전: #REF!
Name 사업명: [2]표지!$B$43

Sheet 테이블정의서
A1: PONKIDS | H1: 공통코드 정리
A4: 순번 | B4: 코드 | C4: 코드 이름 | D4: 코드 설명 | E4: 시스템 필수 코드 여부 | F4: 코드 상세 이름 | G4: 코드 상세 설명 | H4: 코드 상세 값
A5: 1 | B5: BAN_TOP_CD | C5: 배너 메인 상단 | D5: 메인 배너 중 상단의 이벤트 배너 | E5: Y
A6: 2 | B6: BAN_BOT_CD | C6: 배너 메인 하단 클래스 | D6: 메인 배너 중 하단의 클래스 | E6: Y
A7: 3 | B7: CLASS_CATE1_CD | C7: 클래스 카테고리 1차분류 | D7: 클래스 카테고리 1차분류에 해당하는 코드 | E7: Y
A8: 4 | B8: CLASS_CATE2_CD | C8: 클래스 카테고리 2차분류 | D8: 클래스 카테고리 2차분류에 해당하는 코드 | E8: Y
A9: 5 | B9: DAY_7_CD | C9: 요일 | D9: 월~일 요일별 코드 | E9: Y
A10: 6 | B10: BBS_SE_CD | C10: 게시판 구분 코드 | D10: 게시판 종류 구분 코드 | E10: Y
A11: 7 | B11: COUNTRY_CD | C11: 국가 구분 코드 | D11: 국가 구분 코드 | E11: Y | F11: 가나 | G11: 가나 | H11: 가나
A12: 8 | B12: COUNTRY_CD | C12: 국가 구분 코드 | D12: 국가 구분 코드 | E12: Y | F12: 가봉 | G12: 가봉 | H12: 가봉
A13: 9 | B13: COUNTRY_CD | C13: 국가 구분 코드 | D13: 국가 구분 코드 | E13: Y | F13: 가이아나 | G13: 가이아나 | H13: 가이아나
A14: 10 | B14: COUNTRY_CD | C14: 국가 구분 코드 | D14: 국가 구분 코드 | E14: Y | F14: 감비아 | G14: 감비아 | H14: 감비아
A15: 11 | B15: COUNTRY_CD | C15: 국가 구분 코드 | D15: 국가 구분 코드 | E15: Y | F15: 과테말라 | G15: 과테말라 | H15: 과테말라
A16: 12 | B16: COUNTRY_CD | C16: 국가 구분 코드 | D16: 국가 구분 코드 | E16: Y | F16: 괌 | G16: 괌 | H16: 괌
A17: 13 | B17: COUNTRY_CD | C17: 국가 구분 코드 | D17: 국가 구분 코드 | E17: Y | F17: 그레나다 | G17: 그레나다 | H17: 그레나다
A18: 14 | B18: COUNTRY_CD | C18: 국가 구분 코드 | D18: 국가 구분 코드 | E18: Y | F18: 그리스 | G18: 그리스 | H18: 그리스
A19: 15 | B19: COUNTRY_CD | C19: 국가 구분 코드 | D19: 국가 구분 코드 | E19: Y | F19: 기니 | G19: 기니 | H19: 기니
A20: 16 | B20: COUNTRY_CD | C20: 국가 구분 코드 | D20: 국가 구분 코드 | E20: Y | F20: 기니비사우 | G20: 기니비사우 | H20: 기니비사우
A21: 17 | B21: COUNTRY_CD | C21: 국가 구분 코드 | D21: 국가 구분 코드 | E21: Y | F21: 나미비아 | G21: 나미비아 | H21: 나미비아
A22: 18 | B22: COUNTRY_CD | C22: 국가 구분 코드 | D22: 국가 구분 코드 | E22: Y | F22: 나우루 | G22: 나우루 | H22: 나우루
... A224: 220 | B224: COUNTRY_CD | C224: 국가 구분 코드 | D224: 국가 구분 코드 | E224: Y | F224: 홍콩 | G224: 홍콩 | H224: 홍콩

Sheet 공통코드추가신청
C1: 손실보상시스템 고도화 및 운영관리
C3: 기존생성코드삭제 | D3: CM619~CM644 | E3: CM647, CM648, CM649
M4: 아래에는 배열 함수를 사용한다. 배열 함수를 사용할떄에는 셀에서 (Ctrl + Shift + Enter ) 를 입력한다.
C6: 코드 | D6: 코드명 | E6: 코드설명 | F6: 유효값 | G6: 유효값명 | H6: 유효값설명 | I6: 비고
C7: CM619 | D7: 환수예정구분코드 | E7: 환수예정 구분을 관리하는 코드. | F7: 01 | G7: 환수예정대상 | H7: 환수예정대상 | J7: ="("&F7&")"&" "&G7 -> (01) 환수예정대상 | K7: CM619 | L7: 환수예정구분코드 | M7: {=_xlfn.TEXTJOIN(", ",TRUE,IF($C$7:$C$205=K7,$J$7:$J$205,""))} -> (01) 환수예정대상, (91) 환수비대상(정산완료), (92) 환수비대상(정산예상) | U7: {=INDEX($C$7:$C$130,MATCH(0,COUNTIF($U$3,$C$7:$C$130),0))} -> CM619
C8: CM619 | D8: 환수예정구분코드 | E8: 환수예정 구분을 관리하는 코드. | F8: 91 | G8: 환수비대상(정산완료) | H8: 환수비대상(정산완료) | J8: ="("&F8&")"&" "&G8 -> (91) 환수비대상(정산완료) | K8: CM620 | L8: 정산처리구분코드 | M8: {=_xlfn.TEXTJOIN(", ",TRUE,IF($C$7:$C$205=K8,$J$7:$J$205,""))} -> (01) 정산완료, (02) 정산예정, (03) 환수예정 | U8: {=INDEX($C$7:$C$130,MATCH(0,COUNTIF($U$3,$C$7:$C$130),0))} -> CM619
C9: CM619 | D9: 환수예정구분코드 | E9: 환수예정 구분을 관리하는 코드. | F9: 92 | G9: 환수비대상(정산예상) | H9: 환수비대상(정산예상) | J9: ="("&F9&")"&" "&G9 -> (92) 환수비대상(정산예상) | K9: CM621 | L9: 환수심의유형구분코드 | M9: {=_xlfn.TEXTJOIN(", ",TRUE,IF($C$7:$C$205=K9,$J$7:$J$205,""))} -> (10) 환수처분사전심의, (20) 환수처분확정심의, (30) 환수이의신청심의 | U9: {=INDEX($C$7:$C$130,MATCH(0,COUNTIF($U$3,$C$7:$C$130),0))} -> CM619
C10: CM620 | D10: 정산처리구분코드 | E10: 정산 처리시 정산금액의 정산 상태를 구분하기 위한 코드. | F10: 01 | G10: 정산완료 | H10: 정산완료 | J10: ="("&F10&")"&" "&G10 -> (01) 정산완료 | K10: CM622 | L10: 환수심의진행상태코드 | M10: {=_xlfn.TEXTJOIN(", ",TRUE,IF($C$7:$C$205=K10,$J$7:$J$205,""))} -> (00) 해당없음, (11) 심의대상, (12) 심의보류, (13) 심의중, (14) 심의완료 | U10: {=INDEX($C$7:$C$130,MATCH(0,COUNTIF($U$3,$C$7:$C$130),0))} -> CM619
C11: CM620 | D11: 정산처리구분코드 | E11: 정산 처리시 정산금액의 정산 상태를 구분하기 위한 코드. | F11: 02 | G11: 정산예정 | H11: 정산예정 | J11: ="("&F11&")"&" "&G11 -> (02) 정산예정 | K11: CM623 | L11: 환수심의처분결과코드 | M11: {=_xlfn.TEXTJOIN(", ",TRUE,IF($C$7:$C$205=K11,$J$7:$J$205,""))} -> (00) 해당없음, (01) 환수대상, (02) 대상아님 | U11: {=INDEX($C$7:$C$130,MATCH(0,COUNTIF($U$3,$C$7:$C$130),0))} -> CM619
C12: CM620 | D12: 정산처리구분코드 | E12: 정산 처리시 정산금액의 정산 상태를 구분하기 위한 코드. | F12: 03 | G12: 환수예정 | H12: 환수예정 | J12: ="("&F12&")"&" "&G12 -> (03) 환수예정 | K12: CM624 | L12: 환수유형코드 | M12: {=_xlfn.TEXTJOIN(", ",TRUE,IF($C$7:$C$205=K12,$J$7:$J$205,""))} -> (01) 허위청구, (02) 과다청구, (03) 목적외사용, (04) 오지급 | U12: {=INDEX($C$7:$C$130,MATCH(0,COUNTIF($U$3,$C$7:$C$130),0))} -> CM619
C13: CM621 | D13: 환수심의유형구분코드 | E13: 환수심의 유형를 구분하기 위한 코드. | F13: 10 | G13: 환수처분사전심의 | H13: 환수처분사전심의 | J13: ="("&F13&")"&" "&G13 -> (10) 환수처분사전심의 | K13: CM626 | L13: 환수결과코드 | M13: {=_xlfn.TEXTJOIN(", ",TRUE,IF($C$7:$C$205=K13,$J$7:$J$205,""))} -> (01) 환수완료, (91) 미납종료(전체금액), (92) 미납종료(일부금액) | U13: {=INDEX($C$7:$C$130,MATCH(0,COUNTIF($U$3,$C$7:$C$130),0))} -> CM619
C14: CM621 | D14: 환수심의유형구분코드 | E14: 환수심의 유형를 구분하기 위한 코드. | F14: 20 | G14: 환수처분확정심의 | H14: 환수처분확정심의 | J14: ="("&F14&")"&" "&G14 -> (20) 환수처분확정심의 | K14: CM627 | L14: 환수민원신청방법코드 | M14: {=_xlfn.TEXTJOIN(", ",TRUE,IF($C$7:$C$205=K14,$J$7:$J$205,""))} -> (01) 온라인, (02) 현장접수, (99) 기타
C15: CM621 | D15: 환수심의유형구분코드 | E15: 환수심의 유형를 구분하기 위한 코드. | F15: 30 | G15: 환수이의신청심의 | H15: 환수이의신청심의 | J15: ="("&F15&")"&" "&G15 -> (30) 환수이의신청심의 | K15: CM629 | L15: 환수이의신청진행상태코드 | M15: {=_xlfn.TEXTJOIN(", ",TRUE,IF($C$7:$C$205=K15,$J$7:$J$205,""))} -> (11) 환수이의신청 등록, (12) 환수이의신청 접수, (21) 회계법인산정 요청 , (25) 회계법인산정 완료, (31) 환수이의신청 심의요청, (32) 환수이의신청 심의보류, (33) 환수이의신청 심의중, (34) 환수이의신청 심의완료
C16: CM622 | D16: 환수심의진행상태코드 | E16: 환수심의 진행상태를 관리하는 코드 | F16: 00 | G16: 해당없음 | H16: 해당없음 | J16: ="("&F16&")"&" "&G16 -> (00) 해당없음 | K16: CM630 | L16: 환수이의신청회계법인결과코드 | M16: {=_xlfn.TEXTJOIN(", ",TRUE,IF($C$7:$C$205=K16,$J$7:$J$205,""))} -> (01) 변경없음, (02) 과소, (03) 과대
C17: CM622 | D17: 환수심의진행상태코드 | E17: 환수처분심의 진행상태를 관리하는 코드 | F17: 11 | G17: 심의대상 | H17: 심의대상 | J17: ="("&F17&")"&" "&G17 -> (11) 심의대상 | K17: CM631 | L17: 환수통지유형코드 | M17: {=_xlfn.TEXTJOIN(", ",TRUE,IF($C$7:$C$205=K17,$J$7:$J$205,""))} -> (01) 환수처분사전통지서, (02) 환수통지서, (03) 환수이의신청결과통지서, (04) 환수독촉통지서
C18: CM622 | D18: 환수심의진행상태코드 | E18: 환수처분심의 진행상태를 관리하는 코드 | F18: 12 | G18: 심의보류 | H18: 심의보류 | J18: ="("&F18&")"&" "&G18 -> (12) 심의보류 | K18: CM632 | L18: 환수통지수집대상코드 | M18: {=_xlfn.TEXTJOIN(", ",TRUE,IF($C$7:$C$205=K18,$J$7:$J$205,""))} -> (01) 최초통지[서면], (02) 재수집통지[서면], (03) 재수집통지[전자], (04) 개별발송
C19: CM622 | D19: 환수심의진행상태코드 | E19: 환수처분심의 진행상태를 관리하는 코드 | F19: 13 | G19: 심의중 | H19: 심의중 | J19: ="("&F19&")"&" "&G19 -> (13) 심의중 | K19: CM633 | L19: 환수통지방법코드 | M19: {=_xlfn.TEXTJOIN(", ",TRUE,IF($C$7:$C$205=K19,$J$7:$J$205,""))} -> (01) 시스템통지, (02) 서면통지, (03) 전자통지, (04) 공시송달
C20: CM622 | D20: 환수심의진행상태코드 | E20: 환수처분심의 진행상태를 관리하는 코드 | F20: 14 | G20: 심의완료 | H20: 심의완료 | J20: ="("&F20&")"&" "&G20 -> (14) 심의완료 | K20: CM634 | L20: 납부일정등록사유코드 | M20: {=_xlfn.TEXTJOIN(", ",TRUE,IF($C$7:$C$205=K20,$J$7:$J$205,""))} -> (10) 환수처분, (20) 환수이의신청처분, (30) 분할납부승인, (40) 상환유예승인, (50) 중도상환승인, (60) 독촉납부전환, (70) 독촉납부미납
C21: CM623 | D21: 환수심의처분결과코드 | E21: 환수심의 처분 결과를 관리하는 코드 | F21: 00 | G21: 해당없음 | H21: 해당없음 | J21: ="("&F21&")"&" "&G21 -> (00) 해당없음 | K21: CM635 | L21: 납부유형코드 | M21: {=_xlfn.TEXTJOIN(", ",TRUE,IF($C$7:$C$205=K21,$J$7:$J$205,""))} -> (10) 최초납부, (20) 분할납부, (30) 상환유예, (40) 중도상환, (50) 독촉납부
C22: CM623 | D22: 환수심의처분결과코드 | E22: 환수심의 처분 결과를 관리하는 코드 | F22: 01 | G22: 환수대상 | H22: 환수대상 | J22: ="("&F22&")"&" "&G22 -> (01) 환수대상 | K22: CM636 | L22: 납부방법코드 | M22: {=_xlfn.TEXTJOIN(", ",TRUE,IF($C$7:$C$205=K22,$J$7:$J$205,""))} -> (01) 일시납부, (02) 분할납부
C23: CM623 | D23: 환수심의처분결과코드 | E23: 환수심의 처분 결과를 관리하는 코드 | F23: 02 | G23: 대상아님 | H23: 대상아님 | J23: ="("&F23&")"&" "&G23 -> (02) 대상아님 | K23: CM637 | L23: 납부상세유형코드 | M23: {=_xlfn.TEXTJOIN(", ",TRUE,IF($C$7:$C$205=K23,$J$7:$J$205,""))} -> (01) 정기분, (02) 미납분, (04) 독촉분
C24: CM624 | D24: 환수유형코드 | E24: 환수의 유형을 내용을 관리하는 코드 | F24: 01 | G24: 허위청구 | H24: 허위청구 | J24: ="("&F24&")"&" "&G24 -> (01) 허위청구 | K24: CM638 | L24: 가상계좌상태코드 | M24: {=_xlfn.TEXTJOIN(", ",TRUE,IF($C$7:$C$205=K24,$J$7:$J$205,""))} -> (01) 발급요청, (02) 발급완료, (03) 기간만료, (91) 삭제요청, (92) 삭제완료
C25: CM624 | D25: 환수유형코드 | E25: 환수의 유형을 내용을 관리하는 코드 | F25: 02 | G25: 과다청구 | H25: 과다청구 | J25: ="("&F25&")"&" "&G25 -> (02) 과다청구 | K25: CM639 | L25: 납부일정변경신청유형코드 | M25: {=_xlfn.TEXTJOIN(", ",TRUE,IF($C$7:$C$205=K25,$J$7:$J$205,""))} -> (01) 분할납부신청, (02) 중도상환납부신청, (03) 상환유예신청
... C35: CM629 | D35: 환수이의신청진행상태코드 | E35: 환수이의신청 진행상태를 관리하기 위한 코드 | F35: 12 | G35: 환수이의신청 접수 | H35: 환수이의신청 접수 | J35: ="("&F35&")"&" "&G35 -> (12) 환수이의신청 접수 | K35: CM657 | L35: 주소변경사유코드 | M35: {=_xlfn.TEXTJOIN(", ",TRUE,IF($C$7:$C$205=K35,$J$7:$J$205,""))} -> (00) 최초 등록, (01) 대표자 변경, (02) 사업장명 변경, (03) 연락처 변경, (04) 사업장 주소 변경, (05) 고지 수신 주소 변경
C36: CM629 | D36: 환수이의신청진행상태코드 | E36: 환수이의신청 진행상태를 관리하기 위한 코드 | F36: 21 | G36: 회계법인산정 요청 | H36: 회계법인산정 요청 | J36: ="("&F36&")"&" "&G36 -> (21) 회계법인산정 요청 | M36: {=_xlfn.TEXTJOIN(", ",TRUE,IF($C$7:$C$130=K36,$J$7:$J$130,""))}
C37: CM629 | D37: 환수이의신청진행상태코드 | E37: 환수이의신청 진행상태를 관리하기 위한 코드 | F37: 25 | G37: 회계법인산정 완료 | H37: 회계법인산정 완료 | J37: ="("&F37&")"&" "&G37 -> (25) 회계법인산정 완료 | M37: {=_xlfn.TEXTJOIN(", ",TRUE,IF($C$7:$C$130=K37,$J$7:$J$130,""))}
C38: CM629 | D38: 환수이의신청진행상태코드 | E38: 환수이의신청 진행상태를 관리하기 위한 코드 | F38: 31 | G38: 환수이의신청 심의요청 | H38: 환수이의신청 심의요청 | J38: ="("&F38&")"&" "&G38 -> (31) 환수이의신청 심의요청 | M38: {=_xlfn.TEXTJOIN(", ",TRUE,IF($C$7:$C$130=K38,$J$7:$J$130,""))}
C39: CM629 | D39: 환수이의신청진행상태코드 | E39: 환수이의신청 진행상태를 관리하기 위한 코드 | F39: 32 | G39: 환수이의신청 심의보류 | H39: 환수이의신청 심의보류 | J39: ="("&F39&")"&" "&G39 -> (32) 환수이의신청 심의보류 | M39: {=_xlfn.TEXTJOIN(", ",TRUE,IF($C$7:$C$130=K39,$J$7:$J$130,""))}
C40: CM629 | D40: 환수이의신청진행상태코드 | E40: 환수이의신청 진행상태를 관리하기 위한 코드 | F40: 33 | G40: 환수이의신청 심의중 | H40: 환수이의신청 심의중 | J40: ="("&F40&")"&" "&G40 -> (33) 환수이의신청 심의중 | M40: {=_xlfn.TEXTJOIN(", ",TRUE,IF($C$7:$C$130=K40,$J$7:$J$130,""))}
C41: CM629 | D41: 환수이의신청진행상태코드 | E41: 환수이의신청 진행상태를 관리하기 위한 코드 | F41: 34 | G41: 환수이의신청 심의완료 | H41: 환수이의신청 심의완료 | J41: ="("&F41&")"&" "&G41 -> (34) 환수이의신청 심의완료 | M41: {=_xlfn.TEXTJOIN(", ",TRUE,IF($C$7:$C$130=K41,$J$7:$J$130,""))}
C42: CM630 | D42: 환수이의신청회계법인결과코드 | E42: 환수이의신청 회계법인재산정 결과를 관리하기 위한 코드. | F42: 01 | G42: 변경없음 | H42: 변경없음 | J42: ="("&F42&")"&" "&G42 -> (01) 변경없음 | M42: {=_xlfn.TEXTJOIN(", ",TRUE,IF($C$7:$C$130=K42,$J$7:$J$130,""))}
C43: CM630 | D43: 환수이의신청회계법인결과코드 | E43: 환수이의신청 회계법인재산정 결과를 관리하기 위한 코드. | F43: 02 | G43: 과소 | H43: 과소 | J43: ="("&F43&")"&" "&G43 -> (02) 과소 | M43: {=_xlfn.TEXTJOIN(", ",TRUE,IF($C$7:$C$130=K43,$J$7:$J$130,""))}
C44: CM630 | D44: 환수이의신청회계법인결과코드 | E44: 환수이의신청 회계법인재산정 결과를 관리하기 위한 코드. | F44: 03 | G44: 과대 | H44: 과대 | J44: ="("&F44&")"&" "&G44 -> (03) 과대 | M44: {=_xlfn.TEXTJOIN(", ",TRUE,IF($C$7:$C$130=K44,$J$7:$J$130,""))}
C45: CM631 | D45: 환수통지유형코드 | E45: 환수 통지의 유형을 관리하기 위한 코드 | F45: 01 | G45: 환수처분사전통지서 | H45: 환수처분사전통지서 | J45: ="("&F45&")"&" "&G45 -> (01) 환수처분사전통지서 | M45: {=_xlfn.TEXTJOIN(", ",TRUE,IF($C$7:$C$130=K45,$J$7:$J$130,""))}
C46: CM631 | D46: 환수통지유형코드 | E46: 환수 통지의 유형을 관리하기 위한 코드 | F46: 02 | G46: 환수통지서 | H46: 환수통지서 | J46: ="("&F46&")"&" "&G46 -> (02) 환수통지서 | M46: {=_xlfn.TEXTJOIN(", ",TRUE,IF($C$7:$C$130=K46,$J$7:$J$130,""))}
C47: CM631 | D47: 환수통지유형코드 | E47: 환수 통지의 유형을 관리하기 위한 코드 | F47: 03 | G47: 환수이의신청결과통지서 | H47: 환수이의신청결과통지서 | J47: ="("&F47&")"&" "&G47 -> (03) 환수이의신청결과통지서 | M47: {=_xlfn.TEXTJOIN(", ",TRUE,IF($C$7:$C$130=K47,$J$7:$J$130,""))}
... C51: CM632 | D51: 환수통지수집대상코드 | E51: 환수통지시 수집대상 구분을 관리하기 위한 코드. | F51: 03 | G51: 재수집통지[전자] | H51: 재수집통지[전자] | J51: ="("&F51&")"&" "&G51 -> (03) 재수집통지[전자] | M51: {=_xlfn.TEXTJOIN(", ",TRUE,IF($C$7:$C$130=K51,$J$7:$J$130,""))}
C52: CM632 | D52: 환수통지수집대상코드 | E52: 환수통지시 수집대상 구분을 관리하기 위한 코드. | F52: 04 | G52: 개별발송 | H52: 개별발송 | J52: ="("&F52&")"&" "&G52 -> (04) 개별발송
C53: CM633 | D53: 환수통지방법코드 | E53: 환수 통지 방법을 관리하기 위한 코드 | F53: 01 | G53: 시스템통지 | H53: 시스템통지 | J53: ="("&F53&")"&" "&G53 -> (01) 시스템통지 | M53: {=_xlfn.TEXTJOIN(", ",TRUE,IF($C$7:$C$130=K53,$J$7:$J$130,""))}
C54: CM633 | D54: 환수통지방법코드 | E54: 환수 통지 방법을 관리하기 위한 코드 | F54: 02 | G54: 서면통지 | H54: 서면통지 | J54: ="("&F54&")"&" "&G54 -> (02) 서면통지 | M54: {=_xlfn.TEXTJOIN(", ",TRUE,IF($C$7:$C$130=K54,$J$7:$J$130,""))}
...

Sheet 공통코드 한눈에 보기
B5: 코드명 | C5: 코드 | D5: 유효값 리스트
B6: =공통코드추가신청!L7 -> 환수예정구분코드 | C6: =공통코드추가신청!K7 -> CM619 | D6: =공통코드추가신청!M7 -> (01) 환수예정대상, (91) 환수비대상(정산완료), (92) 환수비대상(정산예상)
B7: =공통코드추가신청!L8 -> 정산처리구분코드 | C7: =공통코드추가신청!K8 -> CM620 | D7: =공통코드추가신청!M8 -> (01) 정산완료, (02) 정산예정, (03) 환수예정
B8: =공통코드추가신청!L9 -> 환수심의유형구분코드 | C8: =공통코드추가신청!K9 -> CM621 | D8: =공통코드추가신청!M9 -> (10) 환수처분사전심의, (20) 환수처분확정심의, (30) 환수이의신청심의
B9: =공통코드추가신청!L10 -> 환수심의진행상태코드 | C9: =공통코드추가신청!K10 -> CM622 | D9: =공통코드추가신청!M10 -> (00) 해당없음, (11) 심의대상, (12) 심의보류, (13) 심의중, (14) 심의완료
B10: =공통코드추가신청!L11 -> 환수심의처분결과코드 | C10: =공통코드추가신청!K11 -> CM623 | D10: =공통코드추가신청!M11 -> (00) 해당없음, (01) 환수대상, (02) 대상아님
B11: =공통코드추가신청!L12 -> 환수유형코드 | C11: =공통코드추가신청!K12 -> CM624 | D11: =공통코드추가신청!M12 -> (01) 허위청구, (02) 과다청구, (03) 목적외사용, (04) 오지급
B12: =공통코드추가신청!L13 -> 환수결과코드 | C12: =공통코드추가신청!K13 -> CM626 | D12: =공통코드추가신청!M13 -> (01) 환수완료, (91) 미납종료(전체금액), (92) 미납종료(일부금액)
B13: =공통코드추가신청!L14 -> 환수민원신청방법코드 | C13: =공통코드추가신청!K14 -> CM627 | D13: =공통코드추가신청!M14 -> (01) 온라인, (02) 현장접수, (99) 기타
B14: =공통코드추가신청!L15 -> 환수이의신청진행상태코드 | C14: =공통코드추가신청!K15 -> CM629 | D14: =공통코드추가신청!M15 -> (11) 환수이의신청 등록, (12) 환수이의신청 접수, (21) 회계법인산정 요청 , (25) 회계법인산정 완료, (31) 환수이의신청 심의요청, (32) 환수이의신청 심의보류, (33) 환수이의신청 심의중, (34) 환수이의신청 심의완료
B15: =공통코드추가신청!L16 -> 환수이의신청회계법인결과코드 | C15: =공통코드추가신청!K16 -> CM630 | D15: =공통코드추가신청!M16 -> (01) 변경없음, (02) 과소, (03) 과대
B16: =공통코드추가신청!L17 -> 환수통지유형코드 | C16: =공통코드추가신청!K17 -> CM631 | D16: =공통코드추가신청!M17 -> (01) 환수처분사전통지서, (02) 환수통지서, (03) 환수이의신청결과통지서, (04) 환수독촉통지서
B17: =공통코드추가신청!L18 -> 환수통지수집대상코드 | C17: =공통코드추가신청!K18 -> CM632 | D17: =공통코드추가신청!M18 -> (01) 최초통지[서면], (02) 재수집통지[서면], (03) 재수집통지[전자], (04) 개별발송
... B34: =공통코드추가신청!L35 -> 주소변경사유코드 | C34: =공통코드추가신청!K35 -> CM657 | D34: =공통코드추가신청!M35 -> (00) 최초 등록, (01) 대표자 변경, (02) 사업장명 변경, (03) 연락처 변경, (04) 사업장 주소 변경, (05) 고지 수신 주소 변경

Sheet Sheet1
A1: 손실보상시스템 고도화 및 운영관리 | I1: 코드정의서(업무분류코드)
A3: NO | B3: 코드 | C3: 코드명 | D3: 코드설명 | E3: 삭제여부 | F3: 유효값 | G3: 유효값명 | H3: 유효값설명 | I3: 유효값 삭제여부
A4: 1 | B4: CM574 | C4: 환수처분결과코드 | D4: 환수 대상자의 처분 결과를 관리하는 코드 | E4: N | F4: 01 | G4: 환수대상 | H4: 환수대상 | I4: N | J4: =", ('" & B4 & "', '" & F4 & "', '" & G4 & "', '20221101', '99991231', '" & G4 & "', 'N', NULL, 'N')" -> , ('CM574', '01', '환수대상', '20221101', '99991231', '환수대상', 'N', NULL, 'N')
A5: 2 | F5: 02 | G5: 대상아님 | H5: 대상아님 | I5: N | J5: =", ('" & B5 & "', '" & F5 & "', '" & G5 & "', '20221101', '99991231', '" & G5 & "', 'N', NULL, 'N')" -> , ('', '02', '대상아님', '20221101', '99991231', '대상아님', 'N', NULL, 'N')
A6: 3 | B6: CM575 | C6: 환수처분근거내용코드 | D6: 환수 대상자의 처분 원인이 되는 근거내용을 관리하는 코드 | E6: N | I6: N
A7: 4 | F7: 99 | G7: 기타 | H7: 기타 | I7: N | J7: =", ('" & B7 & "', '" & F7 & "', '" & G7 & "', '20221101', '99991231', '" & G7 & "', 'N', NULL, 'N')" -> , ('', '99', '기타', '20221101', '99991231', '기타', 'N', NULL, 'N')
A8: 5 | B8: CM576 | C8: 환수처분내용코드 | D8: 환수 대상자의 처분 내용을 관리하는 코드 | E8: N | I8: N
F9: 99 | G9: 기타 | H9: 기타 | I9: N | J9: =", ('" & B9 & "', '" & F9 & "', '" & G9 & "', '20221101', '99991231', '" & G9 & "', 'N', NULL, 'N')" -> , ('', '99', '기타', '20221101', '99991231', '기타', 'N', NULL, 'N')
B10: CM577 | C10: 환수법률근거내용코드 | D10: 환수 대상자의 처분 법적근거 및 조문내용을 관리하는 코드 | E10: N | I10: N
F11: 99 | G11: 기타 | H11: 기타 | I11: N | J11: =", ('" & B11 & "', '" & F11 & "', '" & G11 & "', '20221101', '99991231', '" & G11 & "', 'N', NULL, 'N')" -> , ('', '99', '기타', '20221101', '99991231', '기타', 'N', NULL, 'N')
B12: CM554 | C12: 환수유형코드 | D12: 환수의 유형을 코드로 관리함 | E12: N | F12: 01 | G12: 매출미감소 | H12: 매출미감소 | I12: N
F13: 02 | G13: 매출규모초과 | H13: 매출규모초과 | I13: N
F14: 03 | G14: 집합금지/영업제한 위반 | H14: 집합금지/영업제한 위반 | I14: N
F15: 04 | G15: 중복수급 | H15: 중복수급 | I15: N
F16: 05 | G16: 부정수급 | H16: 부정수급 | I16: N
F17: 06 | G17: 오지급 | H17: 오지급 | I17: N
F18: 07 | G18: 이의신청 | H18: 이의신청 | I18: N
F19: 99 | G19: 기타 | H19: 기타 | I19: N
B20: CM578 | C20: 환수유형상세코드 | D20: 환수의 유형의 상세 내용을 코드로 관리함 | E20: N | F20: 01 | G20: PG매출액 오류 | H20: PG매출액 오류 | I20: N | J20: =", ('" & B20 & "', '" & F20 & "', '" & G20 & "', '20221101', '99991231', '" & G20 & "', 'N', NULL, 'N')" -> , ('CM578', '01', 'PG매출액 오류', '20221101', '99991231', 'PG매출액 오류', 'N', NULL, 'N')
F21: 02 | G21: 인프라매출액 오류 | H21: 인프라매출액 오류 | I21: N | J21: =", ('" & B21 & "', '" & F21 & "', '" & G21 & "', '20221101', '99991231', '" & G21 & "', 'N', NULL, 'N')" -> , ('', '02', '인프라매출액 오류', '20221101', '99991231', '인프라매출액 오류', 'N', NULL, 'N')
F22: 03 | G22: 법인사업자 산식 오류 | H22: 법인사업자 산식 오류 | I22: N | J22: =", ('" & B22 & "', '" & F22 & "', '" & G22 & "', '20221101', '99991231', '" & G22 & "', 'N', NULL, 'N')" -> , ('', '03', '법인사업자 산식 오류', '20221101', '99991231', '법인사업자 산식 오류', 'N', NULL, 'N')
F23: 04 | G23: 개업일 오류 | H23: 개업일 오류 | I23: N | J23: =", ('" & B23 & "', '" & F23 & "', '" & G23 & "', '20221101', '99991231', '" & G23 & "', 'N', NULL, 'N')" -> , ('', '04', '개업일 오류', '20221101', '99991231', '개업일 오류', 'N', NULL, 'N')
F24: 99 | G24: 기타 | H24: 기타 | I24: N | J24: =", ('" & B24 & "', '" & F24 & "', '" & G24 & "', '20221101', '99991231', '" & G24 & "', 'N', NULL, 'N')" -> , ('', '99', '기타', '20221101', '99991231', '기타', 'N', NULL, 'N')
B25: CM579 | C25: 환수부과내용코드 | D25: 환수 대상자의 환수 부과 사유 내용을 관리하는 코드 | E25: N | I25: N
F26: 99 | G26: 기타 | H26: 기타 | I26: N | J26: =", ('" & B26 & "', '" & F26 & "', '" & G26 & "', '20221101', '99991231', '" & G26 & "', 'N', NULL, 'N')" -> , ('', '99', '기타', '20221101', '99991231', '기타', 'N', NULL, 'N')
B27: CM580 | C27: 환수근거내용코드 | D27: 환수 대상자의 환수 근거 내용을 관리하는 코드 | E27: N | I27: N
F28: 99 | G28: 기타 | H28: 기타 | I28: N | J28: =", ('" & B28 & "', '" & F28 & "', '" & G28 & "', '20221101', '99991231', '" & G28 & "', 'N', NULL, 'N')" -> , ('', '99', '기타', '20221101', '99991231', '기타', 'N', NULL, 'N')
B29: CM555 | C29: 제재부가구분코드 | D29: 제재 부가 구분정보를 나타내기 위한 기호 체계. | E29: N | F29: 01 | G29: 제재부가금 부과 | H29: 제재부가금 부과 | I29: N
F30: 02 | G30: 제재부가금 감경/감면 | H30: 제재부가금 감경/감면 | I30: N
F31: ZZ | G31: 해당없음 | H31: 해당없음 | I31: N
B32: CM556 | C32: 제재부가사유코드 | D32: 제재 부가 사유정보를 나타내기 위한 기호 체계. | E32: N | F32: 01 | G32: 과다청구 | H32: 과다청구 | I32: N
F33: 02 | G33: 목적외사용 | H33: 목적외사용 | I33: N
F34: 03 | G34: 허위청구 | H34: 허위청구 | I34: N
F35: ZZ | G35: 해당없음 | H35: 해당없음 | I35: N
B36: CM581 | C36: 제재부가예외사유내용코드 | D36: 환수 대상자의 환수금 제재 부가 예외 사유내용을 관리하는 코드 | E36: N | I36: N
F37: 99 | G37: 기타 | H37: 기타 | I37: N | J37: =", ('" & B37 & "', '" & F37 & "', '" & G37 & "', '20221101', '99991231', '" & G37 & "', 'N', NULL, 'N')" -> , ('', '99', '기타', '20221101', '99991231', '기타', 'N', NULL, 'N')
B38: CM582 | C38: 환수납부유형코드 | D38: 환수대상자의 환수납부 유형을 관리하는 코드 | E38: N | F38: 01 | G38: 자진납부 | H38: 자진납부 | I38: N | J38: =", ('" & B38 & "', '" & F38 & "', '" & G38 & "', '20221101', '99991231', '" & G38 & "', 'N', NULL, 'N')" -> , ('CM582', '01', '자진납부', '20221101', '99991231', '자진납부', 'N', NULL, 'N')
F39: 02 | G39: 환수납부 | H39: 환수납부 | I39: N | J39: =", ('" & B39 & "', '" & F39 & "', '" & G39 & "', '20221101', '99991231', '" & G39 & "', 'N', NULL, 'N')" -> , ('', '02', '환수납부', '20221101', '99991231', '환수납부', 'N', NULL, 'N')
F40: 03 | G40: 독촉납부1 | H40: 독촉납부1 | I40: N | J40: =", ('" & B40 & "', '" & F40 & "', '" & G40 & "', '20221101', '99991231', '" & G40 & "', 'N', NULL, 'N')" -> , ('', '03', '독촉납부1', '20221101', '99991231', '독촉납부1', 'N', NULL, 'N')
F41: 04 | G41: 독촉납부2 | H41: 독촉납부2 | I41: N | J41: =", ('" & B41 & "', '" & F41 & "', '" & G41 & "', '20221101', '99991231', '" & G41 & "', 'N', NULL, 'N')" -> , ('', '04', '독촉납부2', '20221101', '99991231', '독촉납부2', 'N', NULL, 'N')
...

Sheet Sheet2
B2: K01 | C2: 환수처분결과 환수대상
B3: K10 | C3: 환수이의신청 접수
B4: K12 | C4: 환수이의신청 처리중
B5: K15 | C5: 환수이의신청 완료
B6: K21 | C6: 환수이의신청결과 환수대상
B7: K20 | C7: 환수이의신청결과 대상아님
B8: K31 | C8: 환수납부 미납
B9: K23 | C9: 환수납부 일부납부
B10: K25 | C10: 환수납부 완납
B11: K29 | C11: 환수금액 완납 종료(환수납부)
B12: K30 | C12: 독촉납부 대상
B13: K31 | C13: 독촉납부 1차 미납
... B30: K91 | C30: 미납금액 환수기관전송
